Workbook

Sheet Instructions
B1: VKS TECH Operational Excellence | vkstech.com
A3: HOW TO USE THIS FORMAT
A4: Format B — Detailed Line-Item Budget
A6: WHEN TO USE FORMAT B
A7: Detail-first budget | B7: Use this when you want to build the budget bottom-up from individual part numbers and quantities, rather than top-down from category totals.
A8: High-stakes approvals | B8: Senior finance / CEO-level approvals usually ask "show me the line items" — Format B answers that without a separate document.
A9: New line / new machine | B9: When a machine is new and there is no prior history to benchmark, line-item quantities + rates are the only defensible way to arrive at a number.
A11: STEP-BY-STEP
A12: 1. Fill header | B12: Enter plant, machine model, FY, prepared-by, approved-by.
A13: 2. Fill quantities (column E) | B13: For each line, enter your honest annual quantity based on shift-count, production hours, or PM schedule.
A14: 3. Fill rates (column F) | B14: Use latest vendor quote or last PO rate. If multiple vendors, use the median.
A15: 4. Let amount auto-calculate | B15: Column G = E × F. Do not overwrite.
A16: 5. Fill "Actual Last FY" (column H) | B16: From SAP/ERP cost-centre dump. Leave blank if unknown.
A17: 6. Review category sub-totals | B17: Each of the 11 sections (A–K) has a sub-total — scan for anything out of line.
A18: 7. Grand Total + Per machine/month | B18: Auto-calculated at the bottom. Use per-machine figure to compare across lines.
A19: 8. Jump to Summary sheet | B19: Category breakdown + % of total is pre-built for your pitch.
A21: COLOUR CODE
A22: Blue text + light-blue fill | B22: INPUT cells — you fill these (quantity, rate, actual last FY).
A23: Black text | B23: FORMULA cells — calculated automatically.
A24: Navy / Teal / Orange fill | B24: Headers / category bands / totals — do not overwrite.
A26: SUBSTITUTIONS & GENERIC NAMING
A27: All brand names are examples only | B27: The "(e.g. Brand-X / Brand-Y)" format shows common substitutes — use whichever your plant has installed.
A28: Vacuum-pump generics | B28: Dry-screw, Roots booster, Rotary-vane, Diffusion are the four generic types. Pick the correct generic row, then write your actual brand in column C.
A29: Oil generics | B29: DP oil (silicone), Rotary oil (mineral/diester), Booster oil (synthetic), Glycol (coolant). Keep the generic description; put brand + grade in column C.
A31: TIPS
A32: One row per SKU / part code | B32: If a spare has 3 sizes, that is 3 rows — easier for procurement later.
A33: Quarterly review | B33: Freeze the budget annually but review consumption quarterly. Adjust quantities, not rates, mid-year.
A34: Contingency 5% | B34: Section K has a 5% contingency placeholder that auto-calculates. Keep it — it prevents panic during unplanned breakdowns.
A35: Per-machine cost | B35: Last block divides total by number of machines. Use it to benchmark between your own lines or against an OEM reference.
A39: VKS TECH — Operational Excellence | vkstech.com | Shop-Floor Finance Series

Sheet Annual Budget
B1: VKS TECH Operational Excellence | vkstech.com
A3: ANNUAL MAINTENANCE BUDGET — VACUUM METALLISER (GENERIC FORMAT)
A4: 11 categories × 76 line items | Bottom-up, brand-neutral, approval-ready
A6: Plant: | B6: __________ | C6: Machine Model: | D6: __________ | E6: FY: | F6: __________ | G6: Prepared by: | H6: __________ | I6: Approved by: __________
A8: Sr. | B8: Item Description | C8: Specification / Example Brands | D8: UOM | E8: Qty/Year | F8: Rate (₹) | G8: Amount (₹) | H8: Actual Last FY (₹) | I8: Remarks
A9: A. CONSUMABLES — EVAPORATION SYSTEM
A10: 1 | B10: Ceramic Evaporation Boats | C10: BN / TiB₂ composite — standard OEM size | D10: Nos | E10: 500 | F10: 850 | G10: =E10*F10 -> 425000 | I10: Boat life 8–24 hrs; ~2–3 per shift
A11: 2 | B11: Aluminium Wire 1.5mm (99.99% pure) | C11: 4N purity — e.g. ALCAN / Fenglu / generic equivalent | D11: Kg | E11: 12000 | F11: 280 | G11: =E11*F11 -> 3360000 | I11: ~1000 kg/month; check CoA each lot
A12: 3 | B12: Aluminium Wire 2.0mm (high-OD grade) | C12: 4N purity — e.g. AlBond / Vijay Metal / generic | D12: Kg | E12: 3000 | F12: 290 | G12: =E12*F12 -> 870000 | I12: High OD / AlBond products
A13: 4 | B13: Graphite Tape | C13: Boat-to-copper contact strip — generic | D13: Rolls | E13: 24 | F13: 450 | G13: =E13*F13 -> 10800 | I13: ~2 rolls/month
A14: 5 | B14: Boron Nitride Spray | C14: Shield release agent — e.g. ZYP / MT / generic | D14: Cans | E14: 36 | F14: 1200 | G14: =E14*F14 -> 43200 | I14: ~3 cans/month
A15: 6 | B15: Wire Feeder Pressure Springs | C15: Pressure-roller springs — generic OEM | D15: Sets | E15: 24 | F15: 350 | G15: =E15*F15 -> 8400 | I15: Monthly replacement — critical PM
A16: 7 | B16: Wire Feeder Guide Spouts | C16: Wear-item guide nozzle — generic OEM | D16: Nos | E16: 48 | F16: 280 | G16: =E16*F16 -> 13440 | I16: Monthly replacement
A17: 8 | B17: Wire Feeder Drive Wheels | C17: Grooved wheel — 3 positions per wheel | D17: Nos | E17: 8 | F17: 1800 | G17: =E17*F17 -> 14400 | I17: Rotate groove monthly; replace when all 3 worn
A18: SUBTOTAL — A. CONSUMABLES — EVAPORATION SYSTEM | G18: =SUM(G11:G17) -> 4320240 | H18: =SUM(H11:H17) -> 0
A19: B. VACUUM SYSTEM — CONSUMABLES & OILS
A20: 9 | B20: Chamber Door O-Ring (Main Seal) | C20: Viton — machine-specific size | D20: Nos | E20: 12 | F20: 3500 | G20: =E20*F20 -> 42000 | I20: Replace on damage; inspect every cycle
A21: 10 | B21: Window / Port O-Rings | C21: Viton — various sizes | D21: Set | E21: 12 | F21: 1500 | G21: =E21*F21 -> 18000 | I21: Monthly inspection
A22: 11 | B22: Feed-through O-Rings | C22: Water / electrical feed-through — Viton | D22: Set | E22: 6 | F22: 2000 | G22: =E22*F22 -> 12000 | I22: Replace on leak detection
A23: 12 | B23: Vacuum Grease (silicone) | C23: e.g. Dow Corning / Apiezon L / generic | D23: Tubes | E23: 12 | F23: 800 | G23: =E23*F23 -> 9600 | I23: For O-ring lubrication only
A24: 13 | B24: Dry-Screw Pump Oil | C24: Diester-base ISO-VG 100 — e.g. Busch VE 101 / Leybold LVO 210 / Edwards 15 / generic | D24: Litres | E24: 8 | F24: 2200 | G24: =E24*F24 -> 17600 | I24: ~2 L per machine × 2 changes/year
A25: 14 | B25: Dry-Screw Pump Coolant | C25: 40% glycol + 60% water ready-mix — OEM spec | D25: Litres | E25: 60 | F25: 180 | G25: =E25*F25 -> 10800 | I25: ~29 L per machine; annual change
A26: 15 | B26: Roots Booster Pump Oil | C26: Synthetic lubricant — e.g. Anderol 555 / Aerzen / generic | D26: Litres | E26: 8 | F26: 3500 | G26: =E26*F26 -> 28000 | I26: 5000-hr service interval
A27: 16 | B27: Diffusion Pump Oil | C27: High-vacuum silicone — e.g. Santovac 5 / Dow 704 / 705 / CVC-Si-4 / generic | D27: Litres | E27: 10 | F27: 8500 | G27: =E27*F27 -> 85000 | I27: ~4–5 L per DP; annual change
A28: 17 | B28: Rotary-Vane Pump Oil | C28: Mineral / semi-synthetic — e.g. Busch R530 / Leybold LVO 108 / Edwards 19 / generic | D28: Litres | E28: 20 | F28: 650 | G28: =E28*F28 -> 13000 | I28: Per PM schedule
A29: 18 | B29: Pump Inlet Filter Element | C29: Replacement filter — generic OEM | D29: Nos | E29: 4 | F29: 4500 | G29: =E29*F29 -> 18000 | I29: Quarterly replacement
A30: 19 | B30: Exhaust Oil-Mist Filter Element | C30: Atomuffler-type — generic OEM | D30: Nos | E30: 4 | F30: 3200 | G30: =E30*F30 -> 12800 | I30: Quarterly replacement
A31: SUBTOTAL — B. VACUUM SYSTEM — CONSUMABLES & OILS | G31: =SUM(G21:G30) -> 224800 | H31: =SUM(H21:H30) -> 0
A32: C. COOLING SYSTEM
A33: 20 | B33: Ethylene Glycol (chiller concentrate) | C33: Industrial coolant — generic | D33: Litres | E33: 50 | F33: 220 | G33: =E33*F33 -> 11000 | I33: 50% concentration; SG 1.080 at 20 °C
A34: 21 | B34: Y-Strainer Mesh Screen | C34: Main water-supply filter — stainless | D34: Nos | E34: 4 | F34: 650 | G34: =E34*F34 -> 2600 | I34: Clean monthly; replace if damaged
A35: 22 | B35: Chiller Refrigerant (top-up) | C35: R407C / R410A or per OEM | D35: Kg | E35: 5 | F35: 1800 | G35: =E35*F35 -> 9000 | I35: Only if leak detected
A36: 23 | B36: Cooling Tower Chemicals | C36: Biocide + anti-scale — generic | D36: Lot | E36: 12 | F36: 3500 | G36: =E36*F36 -> 42000 | I36: Monthly dosing
A37: 24 | B37: Rotary Union Seal Kit | C37: Chill-drum water connection — e.g. Deublin / Duff-Norton / generic | D37: Kit | E37: 2 | F37: 12000 | G37: =E37*F37 -> 24000 | I37: Replace on leak
A38: SUBTOTAL — C. COOLING SYSTEM | G38: =SUM(G34:G37) -> 77600 | H38: =SUM(H34:H37) -> 0
A39: D. WINDING SYSTEM
A40: 25 | B40: Spreader Roller Rubber Sleeve | C40: Bow-roller cover — e.g. Kickert / Mount Hope / generic | D40: Nos | E40: 4 | F40: 8500 | G40: =E40*F40 -> 34000 | I40: Replace when worn / cracked
A41: 26 | B41: Nip Roller Re-rubberisation | C41: Rewind nip — generic re-rubber service | D41: Nos | E41: 2 | F41: 15000 | G41: =E41*F41 -> 30000 | I41: Annual or on damage
A42: 27 | B42: Expanding Shaft Springs / Keys | C42: e.g. Svecom / Double-E / Goldenrod generic | D42: Set | E42: 2 | F42: 5500 | G42: =E42*F42 -> 11000 | I42: Replace on shaft service
A43: 28 | B43: Shaft Coupling Elements | C43: e.g. ETP / Lenze / generic hub insert | D43: Nos | E43: 4 | F43: 3800 | G43: =E43*F43 -> 15200 | I43: Replace on inspection
...

Sheet Summary
B1: VKS TECH Operational Excellence | vkstech.com
A3: ANNUAL BUDGET SUMMARY — CATEGORY BREAKDOWN
A4: % share of total + variance view — use this as the 1-page approval cover
A6: Sr. | B6: Category | C6: Budget (₹) | D6: Actual Last FY (₹) | E6: % of Total
A7: 1 | B7: A. Consumables — Evaporation | C7: ='Annual Budget'!G18 -> 4320240 | D7: ='Annual Budget'!H18 -> 0 | E7: =IF(C18>0,C7/C18,0) -> 0.71452033
A8: 2 | B8: B. Vacuum System — Consumables & Oils | C8: ='Annual Budget'!G31 -> 224800 | D8: ='Annual Budget'!H31 -> 0 | E8: =IF(C18>0,C8/C18,0) -> 0.037179455
A9: 3 | B9: C. Cooling System | C9: ='Annual Budget'!G38 -> 77600 | D9: ='Annual Budget'!H38 -> 0 | E9: =IF(C18>0,C9/C18,0) -> 0.012834189
A10: 4 | B10: D. Winding System | C10: ='Annual Budget'!G45 -> 72200 | D10: ='Annual Budget'!H45 -> 0 | E10: =IF(C18>0,C10/C18,0) -> 0.011941088
A11: 5 | B11: E. Electrical & Drives | C11: ='Annual Budget'!G57 -> 159800 | D11: ='Annual Budget'!H57 -> 0 | E11: =IF(C18>0,C11/C18,0) -> 0.026429168
A12: 6 | B12: F. Mechanical Spares | C12: ='Annual Budget'!G66 -> 86450 | D12: ='Annual Budget'!H66 -> 0 | E12: =IF(C18>0,C12/C18,0) -> 0.014297882
A13: 7 | B13: G. OEM Service Contracts | C13: ='Annual Budget'!G75 -> 595000 | D13: ='Annual Budget'!H75 -> 0 | E13: =IF(C18>0,C13/C18,0) -> 0.098406477
A14: 8 | B14: H. Safety, PPE & Compliance | C14: ='Annual Budget'!G85 -> 121440 | D14: ='Annual Budget'!H85 -> 0 | E14: =IF(C18>0,C14/C18,0) -> 0.020084845
A15: 9 | B15: I. Calibration & Testing | C15: ='Annual Budget'!G94 -> 63200 | D15: ='Annual Budget'!H94 -> 0 | E15: =IF(C18>0,C15/C18,0) -> 0.010452587
A16: 10 | B16: J. Cleaning & Housekeeping | C16: ='Annual Budget'!G101 -> 25320 | D16: ='Annual Budget'!H101 -> 0 | E16: =IF(C18>0,C16/C18,0) -> 0.0041876504
A17: 11 | B17: K. Miscellaneous & Contingency | C17: ='Annual Budget'!G107 -> 300300 | D17: ='Annual Budget'!H107 -> 0 | E17: =IF(C18>0,C17/C18,0) -> 0.049666328
A18: ★ | B18: GRAND TOTAL | C18: =SUM(C7:C17) -> 6046350 | D18: =SUM(D7:D17) -> 0 | E18: =IF(C18>0,SUM(E7:E17),0) -> 1
A21: VKS TECH — Operational Excellence | vkstech.com | Shop-Floor Finance Series
